[W 18:20:48.030 NotebookApp] WARNING: The notebook server is listening on all IP addresses and not using encryption. This is not recommended.
[I 18:20:48.032 NotebookApp] Serving notebooks from local directory: /home/ubuntu/jupyter_projects
[I 18:20:48.032 NotebookApp] Jupyter Notebook 6.4.4 is running at:
[I 18:20:48.032 NotebookApp] http://ip-172-31-2-21:8888/
[I 18:20:48.032 NotebookApp] Use Control-C to stop this server and shut down all kernels (twice to skip confirmation).
[I 18:20:57.102 NotebookApp] 302 GET / (64.187.185.116) 0.550000ms
[W 18:20:57.131 NotebookApp] Forbidden
[W 18:20:57.131 NotebookApp] 403 GET /api/sessions?_=1634149038321 (64.187.185.116) 0.880000ms referer=http://3.14.129.150:8888/tree?
[W 18:20:57.136 NotebookApp] Forbidden
[W 18:20:57.136 NotebookApp] 403 GET /api/config/tree?_=1634149038318 (64.187.185.116) 0.730000ms referer=http://3.14.129.150:8888/tree?
[W 18:20:57.137 NotebookApp] Forbidden
[W 18:20:57.138 NotebookApp] 403 GET /api/terminals?_=1634149038320 (64.187.185.116) 0.820000ms referer=http://3.14.129.150:8888/tree?
[W 18:20:57.138 NotebookApp] Forbidden
[W 18:20:57.139 NotebookApp] 403 GET /api/kernelspecs (64.187.185.116) 0.630000ms referer=http://3.14.129.150:8888/tree?
[W 18:20:57.160 NotebookApp] Forbidden
[W 18:20:57.160 NotebookApp] 403 GET /api/terminals?_=1634149038322 (64.187.185.116) 0.590000ms referer=http://3.14.129.150:8888/tree?
[W 18:20:57.161 NotebookApp] Forbidden
[W 18:20:57.162 NotebookApp] 403 GET /api/config/common?_=1634149038319 (64.187.185.116) 0.590000ms referer=http://3.14.129.150:8888/tree?
[W 18:20:57.163 NotebookApp] Forbidden
[W 18:20:57.163 NotebookApp] 403 GET /api/contents?type=directory&_=1634149038323 (64.187.185.116) 0.610000ms referer=http://3.14.129.150:8888/tree?
[I 18:20:57.165 NotebookApp] 302 GET /tree? (64.187.185.116) 0.530000ms
[I 18:20:57.625 NotebookApp] 302 GET / (64.187.185.116) 0.660000ms
[I 18:20:57.658 NotebookApp] 302 GET /tree? (64.187.185.116) 0.450000ms
[I 18:21:01.144 NotebookApp] 302 POST /login?next=%2Ftree%3F (64.187.185.116) 105.540000ms
/usr/lib/python3.8/json/encoder.py:257: UserWarning: date_default is deprecated since jupyter_client 7.0.0. Use jupyter_client.jsonutil.json_default.
  return _iterencode(o, 0)
[I 18:21:06.068 NotebookApp] Creating new notebook in /scripts
[W 18:21:07.015 NotebookApp] 404 GET /nbextensions/widgets/notebook/js/extension.js?v=20211013182047 (64.187.185.116) 7.600000ms referer=http://3.14.129.150:8888/notebooks/scripts/Untitled.ipynb?kernel_name=python3
ERROR:asyncio:Exception in callback <TaskWakeupMethWrapper object at 0x7f3bd8c684c0>(<Future finished result=None>)
handle: <Handle <TaskWakeupMethWrapper object at 0x7f3bd8c684c0>(<Future finished result=None>)>
Traceback (most recent call last):
  File "/usr/lib/python3.8/asyncio/events.py", line 81, in _run
    self._context.run(self._callback, *self._args)
RuntimeError: Cannot enter into task <Task pending name='Task-9' coro=<HTTP1ServerConnection._server_request_loop() running at /home/ubuntu/.local/lib/python3.8/site-packages/tornado/http1connection.py:823> wait_for=<Future finished result=None> cb=[IOLoop.add_future.<locals>.<lambda>() at /home/ubuntu/.local/lib/python3.8/site-packages/tornado/ioloop.py:688]> while another task <Task pending name='Task-58' coro=<MappingKernelManager.start_kernel() running at /home/ubuntu/.local/lib/python3.8/site-packages/notebook/services/kernels/kernelmanager.py:176> cb=[IOLoop.add_future.<locals>.<lambda>() at /home/ubuntu/.local/lib/python3.8/site-packages/tornado/ioloop.py:688]> is being executed.
[I 18:21:07.135 NotebookApp] Kernel started: f8bbc452-a63e-48c1-b24c-afdd1ac3c8ee, name: python3
[W 18:21:50.448 NotebookApp] 404 GET /nbextensions/widgets/notebook/js/extension.js?v=20211013182047 (64.187.185.116) 1.340000ms referer=http://3.14.129.150:8888/notebooks/scripts/count_zip.ipynb
ERROR:asyncio:Exception in callback <TaskWakeupMethWrapper object at 0x7f3bda184130>(<Future finis...uest\r\n\r\n'>)
handle: <Handle <TaskWakeupMethWrapper object at 0x7f3bda184130>(<Future finis...uest\r\n\r\n'>)>
Traceback (most recent call last):
  File "/usr/lib/python3.8/asyncio/events.py", line 81, in _run
    self._context.run(self._callback, *self._args)
RuntimeError: Cannot enter into task <Task pending name='Task-11' coro=<HTTP1ServerConnection._server_request_loop() running at /home/ubuntu/.local/lib/python3.8/site-packages/tornado/http1connection.py:823> wait_for=<Future finished result=b'GET /api/co...quest\r\n\r\n'> cb=[IOLoop.add_future.<locals>.<lambda>() at /home/ubuntu/.local/lib/python3.8/site-packages/tornado/ioloop.py:688]> while another task <Task pending name='Task-47' coro=<MappingKernelManager.start_kernel() running at /home/ubuntu/.local/lib/python3.8/site-packages/notebook/services/kernels/kernelmanager.py:176> cb=[IOLoop.add_future.<locals>.<lambda>() at /home/ubuntu/.local/lib/python3.8/site-packages/tornado/ioloop.py:695]> is being executed.
[I 18:21:50.602 NotebookApp] Kernel started: 4db675b7-423d-466d-8eaa-6787b6ce4ec4, name: python3
[I 18:23:07.151 NotebookApp] Saving file at /scripts/Untitled.ipynb
[I 18:23:25.492 NotebookApp] Saving file at /scripts/Untitled.ipynb
[I 18:23:26.600 NotebookApp] Starting buffering for f8bbc452-a63e-48c1-b24c-afdd1ac3c8ee:52cd68e7bbbd41c9a464cd048a2d0222
[I 18:23:35.305 NotebookApp] interrupted
Serving notebooks from local directory: /home/ubuntu/jupyter_projects
2 active kernels
Jupyter Notebook 6.4.4 is running at:
http://ip-172-31-2-21:8888/
Shutdown this notebook server (y/[n])? [C 18:23:36.454 NotebookApp] Shutdown confirmed
[I 18:23:36.455 NotebookApp] Shutting down 2 kernels
[I 18:23:36.455 NotebookApp] Kernel shutdown: f8bbc452-a63e-48c1-b24c-afdd1ac3c8ee
[I 18:23:36.661 NotebookApp] Kernel shutdown: 4db675b7-423d-466d-8eaa-6787b6ce4ec4
[I 18:23:36.770 NotebookApp] Shutting down 0 terminals
